[NbConvertApp] Converting notebook sisso_analysis.ipynb to notebook
Traceback (most recent call last):
  File "/home/ajhoffman/miniforge3/envs/htvs/bin/jupyter-nbconvert", line 8, in <module>
    sys.exit(main())
             ^^^^^^
  File "/home/ajhoffman/miniforge3/envs/htvs/lib/python3.11/site-packages/jupyter_core/application.py", line 283, in launch_instance
    super().launch_instance(argv=argv, **kwargs)
  File "/home/ajhoffman/miniforge3/envs/htvs/lib/python3.11/site-packages/traitlets/config/application.py", line 1075, in launch_instance
    app.start()
  File "/home/ajhoffman/miniforge3/envs/htvs/lib/python3.11/site-packages/nbconvert/nbconvertapp.py", line 420, in start
    self.convert_notebooks()
  File "/home/ajhoffman/miniforge3/envs/htvs/lib/python3.11/site-packages/nbconvert/nbconvertapp.py", line 597, in convert_notebooks
    self.convert_single_notebook(notebook_filename)
  File "/home/ajhoffman/miniforge3/envs/htvs/lib/python3.11/site-packages/nbconvert/nbconvertapp.py", line 563, in convert_single_notebook
    output, resources = self.export_single_notebook(
                        ^^^^^^^^^^^^^^^^^^^^^^^^^^^^
  File "/home/ajhoffman/miniforge3/envs/htvs/lib/python3.11/site-packages/nbconvert/nbconvertapp.py", line 487, in export_single_notebook
    output, resources = self.exporter.from_filename(
                        ^^^^^^^^^^^^^^^^^^^^^^^^^^^^
  File "/home/ajhoffman/miniforge3/envs/htvs/lib/python3.11/site-packages/nbconvert/exporters/exporter.py", line 201, in from_filename
    return self.from_file(f, resources=resources, **kw)
           ^^^^^^^^^^^^^^^^^^^^^^^^^^^^^^^^^^^^^^^^^^^^
  File "/home/ajhoffman/miniforge3/envs/htvs/lib/python3.11/site-packages/nbconvert/exporters/exporter.py", line 220, in from_file
    return self.from_notebook_node(
           ^^^^^^^^^^^^^^^^^^^^^^^^
  File "/home/ajhoffman/miniforge3/envs/htvs/lib/python3.11/site-packages/nbconvert/exporters/notebook.py", line 36, in from_notebook_node
    nb_copy, resources = super().from_notebook_node(nb, resources, **kw)
                         ^^^^^^^^^^^^^^^^^^^^^^^^^^^^^^^^^^^^^^^^^^^^^^^
  File "/home/ajhoffman/miniforge3/envs/htvs/lib/python3.11/site-packages/nbconvert/exporters/exporter.py", line 154, in from_notebook_node
    nb_copy, resources = self._preprocess(nb_copy, resources)
                         ^^^^^^^^^^^^^^^^^^^^^^^^^^^^^^^^^^^^
  File "/home/ajhoffman/miniforge3/envs/htvs/lib/python3.11/site-packages/nbconvert/exporters/exporter.py", line 353, in _preprocess
    nbc, resc = preprocessor(nbc, resc)
                ^^^^^^^^^^^^^^^^^^^^^^^
  File "/home/ajhoffman/miniforge3/envs/htvs/lib/python3.11/site-packages/nbconvert/preprocessors/base.py", line 48, in __call__
    return self.preprocess(nb, resources)
           ^^^^^^^^^^^^^^^^^^^^^^^^^^^^^^
  File "/home/ajhoffman/miniforge3/envs/htvs/lib/python3.11/site-packages/nbconvert/preprocessors/execute.py", line 103, in preprocess
    self.preprocess_cell(cell, resources, index)
  File "/home/ajhoffman/miniforge3/envs/htvs/lib/python3.11/site-packages/nbconvert/preprocessors/execute.py", line 124, in preprocess_cell
    cell = self.execute_cell(cell, index, store_history=True)
           ^^^^^^^^^^^^^^^^^^^^^^^^^^^^^^^^^^^^^^^^^^^^^^^^^^
  File "/home/ajhoffman/miniforge3/envs/htvs/lib/python3.11/site-packages/jupyter_core/utils/__init__.py", line 165, in wrapped
    return loop.run_until_complete(inner)
           ^^^^^^^^^^^^^^^^^^^^^^^^^^^^^^
  File "/home/ajhoffman/miniforge3/envs/htvs/lib/python3.11/asyncio/base_events.py", line 654, in run_until_complete
    return future.result()
           ^^^^^^^^^^^^^^^
  File "/home/ajhoffman/miniforge3/envs/htvs/lib/python3.11/site-packages/nbclient/client.py", line 1062, in async_execute_cell
    await self._check_raise_for_error(cell, cell_index, exec_reply)
  File "/home/ajhoffman/miniforge3/envs/htvs/lib/python3.11/site-packages/nbclient/client.py", line 918, in _check_raise_for_error
    raise CellExecutionError.from_cell_and_msg(cell, exec_reply_content)
nbclient.exceptions.CellExecutionError: An error occurred while executing the following cell:
------------------
auc_avs_mini = {}
for metric in best_stab_metrics:
    auc_avs_mini[metric] = auc_comp_mini[metric].mean()
------------------


[0;31m---------------------------------------------------------------------------[0m
[0;31mKeyError[0m                                  Traceback (most recent call last)
File [0;32m~/miniforge3/envs/htvs/lib/python3.11/site-packages/pandas/core/indexes/base.py:3791[0m, in [0;36mIndex.get_loc[0;34m(self, key)[0m
[1;32m   3790[0m [38;5;28;01mtry[39;00m:
[0;32m-> 3791[0m     [38;5;28;01mreturn[39;00m [38;5;28;43mself[39;49m[38;5;241;43m.[39;49m[43m_engine[49m[38;5;241;43m.[39;49m[43mget_loc[49m[43m([49m[43mcasted_key[49m[43m)[49m
[1;32m   3792[0m [38;5;28;01mexcept[39;00m [38;5;167;01mKeyError[39;00m [38;5;28;01mas[39;00m err:

File [0;32mindex.pyx:152[0m, in [0;36mpandas._libs.index.IndexEngine.get_loc[0;34m()[0m

File [0;32mindex.pyx:181[0m, in [0;36mpandas._libs.index.IndexEngine.get_loc[0;34m()[0m

File [0;32mpandas/_libs/hashtable_class_helper.pxi:7080[0m, in [0;36mpandas._libs.hashtable.PyObjectHashTable.get_item[0;34m()[0m

File [0;32mpandas/_libs/hashtable_class_helper.pxi:7088[0m, in [0;36mpandas._libs.hashtable.PyObjectHashTable.get_item[0;34m()[0m

[0;31mKeyError[0m: 'dA_fS'

The above exception was the direct cause of the following exception:

[0;31mKeyError[0m                                  Traceback (most recent call last)
Cell [0;32mIn[72], line 3[0m
[1;32m      1[0m auc_avs_mini [38;5;241m=[39m {}
[1;32m      2[0m [38;5;28;01mfor[39;00m metric [38;5;129;01min[39;00m best_stab_metrics:
[0;32m----> 3[0m     auc_avs_mini[metric] [38;5;241m=[39m [43mauc_comp_mini[49m[43m[[49m[43mmetric[49m[43m][49m[38;5;241m.[39mmean()

File [0;32m~/miniforge3/envs/htvs/lib/python3.11/site-packages/pandas/core/frame.py:3893[0m, in [0;36mDataFrame.__getitem__[0;34m(self, key)[0m
[1;32m   3891[0m [38;5;28;01mif[39;00m [38;5;28mself[39m[38;5;241m.[39mcolumns[38;5;241m.[39mnlevels [38;5;241m>[39m [38;5;241m1[39m:
[1;32m   3892[0m     [38;5;28;01mreturn[39;00m [38;5;28mself[39m[38;5;241m.[39m_getitem_multilevel(key)
[0;32m-> 3893[0m indexer [38;5;241m=[39m [38;5;28;43mself[39;49m[38;5;241;43m.[39;49m[43mcolumns[49m[38;5;241;43m.[39;49m[43mget_loc[49m[43m([49m[43mkey[49m[43m)[49m
[1;32m   3894[0m [38;5;28;01mif[39;00m is_integer(indexer):
[1;32m   3895[0m     indexer [38;5;241m=[39m [indexer]

File [0;32m~/miniforge3/envs/htvs/lib/python3.11/site-packages/pandas/core/indexes/base.py:3798[0m, in [0;36mIndex.get_loc[0;34m(self, key)[0m
[1;32m   3793[0m     [38;5;28;01mif[39;00m [38;5;28misinstance[39m(casted_key, [38;5;28mslice[39m) [38;5;129;01mor[39;00m (
[1;32m   3794[0m         [38;5;28misinstance[39m(casted_key, abc[38;5;241m.[39mIterable)
[1;32m   3795[0m         [38;5;129;01mand[39;00m [38;5;28many[39m([38;5;28misinstance[39m(x, [38;5;28mslice[39m) [38;5;28;01mfor[39;00m x [38;5;129;01min[39;00m casted_key)
[1;32m   3796[0m     ):
[1;32m   3797[0m         [38;5;28;01mraise[39;00m InvalidIndexError(key)
[0;32m-> 3798[0m     [38;5;28;01mraise[39;00m [38;5;167;01mKeyError[39;00m(key) [38;5;28;01mfrom[39;00m [38;5;21;01merr[39;00m
[1;32m   3799[0m [38;5;28;01mexcept[39;00m [38;5;167;01mTypeError[39;00m:
[1;32m   3800[0m     [38;5;66;03m# If we have a listlike key, _check_indexing_error will raise[39;00m
[1;32m   3801[0m     [38;5;66;03m#  InvalidIndexError. Otherwise we fall through and re-raise[39;00m
[1;32m   3802[0m     [38;5;66;03m#  the TypeError.[39;00m
[1;32m   3803[0m     [38;5;28mself[39m[38;5;241m.[39m_check_indexing_error(key)

[0;31mKeyError[0m: 'dA_fS'

